<mujoco model="MagicBotZ1">
  <option gravity='0 0 -9.81' solver='PGS'/>
  <compiler angle="radian" meshdir="../meshes"/>
  <statistic meansize="0.144785" extent="1.23314" center="0.025392 2.0634e-05 -0.245975"/>
  <default>
    <joint damping="0.001" armature="0.01" frictionloss="0.1"/>
  </default>
  <option timestep="0.002"/> 
  <option integrator="implicit"/>

  <asset>
    <texture type="skybox" builtin="gradient" rgb1="0.3 0.5 0.7" rgb2="0 0 0" width="512" height="512" />
    <texture name="texplane" type="2d" builtin="checker" rgb1=".2 .3 .4" rgb2=".1 0.15 0.2" width="512" height="512" mark="cross" markrgb=".8 .8 .8" />
    <material name="matplane" reflectance="0.3" texture="texplane" texrepeat="1 1" texuniform="true" />
    <mesh name="pelvis" file="pelvis.STL"/>
    <mesh name="torso_link" file="torso_link.STL"/>
    <mesh name="right_shoulder_pitch_link" file="right_shoulder_pitch_link.STL"/>
    <mesh name="right_shoulder_roll_link" file="right_shoulder_roll_link.STL"/>
    <mesh name="right_shoulder_yaw_link" file="right_shoulder_yaw_link.STL"/>
    <mesh name="right_elbow_link" file="right_elbow_link.STL"/>
    <mesh name="right_wrist_yaw_link" file="right_wrist_yaw_link.STL"/>
    <mesh name="left_shoulder_pitch_link" file="left_shoulder_pitch_link.STL"/>
    <mesh name="left_shoulder_roll_link" file="left_shoulder_roll_link.STL"/>
    <mesh name="left_shoulder_yaw_link" file="left_shoulder_yaw_link.STL"/>
    <mesh name="left_elbow_link" file="left_elbow_link.STL"/>
    <mesh name="left_wrist_yaw_link" file="left_wrist_yaw_link.STL"/>
    <mesh name="head_link" file="head_link.STL"/>
    <mesh name="right_hip_pitch_link" file="right_hip_pitch_link.STL"/>
    <mesh name="right_hip_roll_link" file="right_hip_roll_link.STL"/>
    <mesh name="right_hip_yaw_link" file="right_hip_yaw_link.STL"/>
    <mesh name="right_knee_link" file="right_knee_link.STL"/>
    <mesh name="right_ankle_pitch_link" file="right_ankle_pitch_link.STL"/>
    <mesh name="right_ankle_roll_link" file="right_ankle_roll_link.STL"/>
    <mesh name="left_hip_pitch_link" file="left_hip_pitch_link.STL"/>
    <mesh name="left_hip_roll_link" file="left_hip_roll_link.STL"/>
    <mesh name="left_hip_yaw_link" file="left_hip_yaw_link.STL"/>
    <mesh name="left_knee_link" content_type="model/stl" file="left_knee_link.STL"/>
    <mesh name="left_ankle_pitch_link" file="left_ankle_pitch_link.STL"/>
    <mesh name="left_ankle_roll_link" content_type="model/stl" file="left_ankle_roll_link.STL"/>
  </asset>

  <worldbody>
    <body name="pelvis"  pos="0 0 0.73">
      <inertial pos="0.0001 0 0.0044" quat="0.707107 0.707107 0 0" mass="3.4083" diaginertia="0.0095 0.0094 0.0056"/>
      <joint name="floating_base" type="free"/>
      <geom type="mesh" contype="0" conaffinity="0" group="1" density="0" rgba="0.75294 0.75294 0.75294 1" mesh="pelvis"/>
      <geom type="sphere" size="0.065" rgba="0.75294 0.75294 0.75294 1"/>
      <camera name="camera1" mode="targetbody" pos="5 0 0.8" euler="1.57 0 1.57" fovy="60"/>
      <camera name="camera2" mode="track" pos="5 0 0.8" euler="1.57 0 1.57" fovy="60"/>
      <site name='imu' size='0.01' pos='0.0 0 0.0'/>
      <body name="left_hip_pitch_link" pos="0 0.06875 0">
        <inertial pos="-0.0002 0.0495 -0.0399" quat="0.951641 0.307212 0 0" mass="1.5089" diaginertia="0.002 0.00181623 0.00118377"/>
        <joint name="left_hip_pitch_joint" pos="0 0 0" axis="0 1 0" range="-2.7925 2.7925" actuatorfrcrange="-120 120" damping="4.0"/>
        <geom type="mesh" contype="0" conaffinity="0" group="1" density="0" rgba="1 1 1 1" mesh="left_hip_pitch_link"/>
        <geom type="mesh" rgba="1 1 1 1" mesh="left_hip_pitch_link"/>
        <body name="left_hip_roll_link" pos="0 0.053724 -0.045579">
          <inertial pos="0.0066 -0.0001 -0.0869" quat="0.968946 0 0.247273 0" mass="1.9215" diaginertia="0.00388217 0.0036 0.00221783"/>
          <joint name="left_hip_roll_joint" pos="0 0 0" axis="1 0 0" range="-0.524 2.967" actuatorfrcrange="-120 120" damping="4.0"/>
          <geom type="mesh" contype="0" conaffinity="0" group="1" density="0" rgba="0.75294 0.75294 0.75294 1" mesh="left_hip_roll_link"/>
          <geom type="mesh" rgba="0.75294 0.75294 0.75294 1" mesh="left_hip_roll_link"/>
          <body name="left_hip_yaw_link" pos="-0.00084052 0 -0.1255">
            <inertial pos="-0.0188 -0.0041 -0.0763" quat="0.97117 -0.0537438 0.205083 -0.109001" mass="0.9002" diaginertia="0.00401624 0.00379582 0.00158794"/>
            <joint name="left_hip_yaw_joint" pos="0 0 0" axis="0 0 1" range="-2.7925 2.7925" actuatorfrcrange="-120 120" damping="4.0"/>
            <geom type="mesh" contype="0" conaffinity="0" group="1" density="0" rgba="0.75294 0.75294 0.75294 1" mesh="left_hip_yaw_link"/>
            <geom type="mesh" rgba="0.75294 0.75294 0.75294 1" mesh="left_hip_yaw_link"/>
            <body name="left_knee_link" pos="-0.052111 0 -0.13729">
              <inertial pos="0.0009 -0.0007 -0.101" quat="0.70981 -3.95743e-05 -0.00819614 0.704345" mass="3.7275" diaginertia="0.0412046 0.0406046 0.00639073"/>
              <joint name="left_knee_joint" pos="0 0 0" axis="0 1 0" range="0 2.653" actuatorfrcrange="-120 120" damping="5.0"/>
              <geom type="mesh" contype="0" conaffinity="0" group="1" density="0" rgba="0.75294 0.75294 0.75294 1" mesh="left_knee_link"/>
              <geom type="mesh" rgba="0.75294 0.75294 0.75294 1" mesh="left_knee_link"/>
              <body name="left_ankle_pitch_link" pos="0 0 -0.34">
                <inertial pos="0.00094063 5.0401e-07 -0.0083154" quat="0.5 0.5 0.5 0.5" mass="0.048544" diaginertia="1.12e-05 1.1e-05 1.033e-05"/>
                <joint name="left_ankle_pitch_joint" pos="0 0 0" axis="0 1 0" range="-0.873 0.524" actuatorfrcrange="-50 50" damping="3.0"/>
                <geom type="mesh" contype="0" conaffinity="0" group="1" density="0" rgba="0.75294 0.75294 0.75294 1" mesh="left_ankle_pitch_link"/>
                <geom type="mesh" rgba="0.75294 0.75294 0.75294 1" mesh="left_ankle_pitch_link"/>
                <body name="left_ankle_roll_link" pos="0 0 -0.018">
                  <inertial pos="0.041316 0.00048241 -0.031752" quat="0 0.724505 0 0.68927" mass="0.7019" diaginertia="0.00240499 0.0023 0.000395012"/>
                  <joint name="left_ankle_roll_joint" pos="0 0 0" axis="1 0 0" range="-0.262 0.262" actuatorfrcrange="-50 50" damping="3.0"/>
                  <geom type="mesh" contype="0" conaffinity="0" group="1" density="0" rgba="0.75294 0.75294 0.75294 1" mesh="left_ankle_roll_link"/>
                  <!-- <geom type="mesh" rgba="0.75294 0.75294 0.75294 1" mesh="left_ankle_roll_link"/> -->
                  <geom type="box" rgba="1 0 0 0.5" pos="0.06 0 -0.038" size="0.10 0.035 0.006" contype="1" conaffinity="15" friction="1 0.005 0.0001"/>
                  <!-- <geom type="sphere" size="0.005" pos="-0.04 0.025 -0.04" rgba="1 0 0 0.5"/>
                  <geom type="sphere" size="0.005" pos="-0.04 -0.025 -0.04" rgba="1 0 0 0.5"/>
                  <geom type="sphere" size="0.005" pos="0.12 0.03 -0.04" rgba="1 0 0 0.5"/>
                  <geom type="sphere" size="0.005" pos="0.12 -0.03 -0.04" rgba="1 0 0 0.5"/> -->
                </body>
              </body>
            </body>
          </body>
        </body>
      </body>
      <body name="right_hip_pitch_link" pos="0 -0.06875 0">
        <inertial pos="-0.0002 -0.0492 -0.0399" quat="0.951641 -0.307212 0 0" mass="1.5089" diaginertia="0.002 0.00181623 0.00118377"/>
        <joint name="right_hip_pitch_joint" pos="0 0 0" axis="0 1 0" range="-2.7925 2.7925" actuatorfrcrange="-120 120" damping="4.0"/>
        <geom type="mesh" contype="0" conaffinity="0" group="1" density="0" rgba="0.75294 0.75294 0.75294 1" mesh="right_hip_pitch_link"/>
        <geom type="mesh" rgba="0.75294 0.75294 0.75294 1" mesh="right_hip_pitch_link"/>
        <body name="right_hip_roll_link" pos="0 -0.053724 -0.045579">
          <inertial pos="0.0069 0.0029 -0.0869" quat="0.968946 0 0.247273 0" mass="1.9215" diaginertia="0.00388217 0.0036 0.00221783"/>
          <joint name="right_hip_roll_joint" pos="0 0 0" axis="1 0 0" range="-2.967 0.524" actuatorfrcrange="-120 120" damping="4.0"/>
          <geom type="mesh" contype="0" conaffinity="0" group="1" density="0" rgba="0.75294 0.75294 0.75294 1" mesh="right_hip_roll_link"/>
          <geom type="mesh" rgba="0.75294 0.75294 0.75294 1" mesh="right_hip_roll_link"/>
          <body name="right_hip_yaw_link" pos="-0.00050599 0.0029213 -0.12555">
            <inertial pos="-0.0188 0.0027 -0.0763" quat="0.97117 0.0537438 0.205083 0.109001" mass="0.9002" diaginertia="0.00401624 0.00379582 0.00158794"/>
            <joint name="right_hip_yaw_joint" pos="0 0 0" axis="0 0 1" range="-2.7925 2.7925" actuatorfrcrange="-120 120" damping="4.0"/>
            <geom type="mesh" contype="0" conaffinity="0" group="1" density="0" rgba="0.75294 0.75294 0.75294 1" mesh="right_hip_yaw_link"/>
            <geom type="mesh" rgba="0.75294 0.75294 0.75294 1" mesh="right_hip_yaw_link"/>
            <body name="right_knee_link" pos="-0.052111 0 -0.13729">
              <inertial pos="0.0009 0.0009 -0.101" quat="0.705029 -0.00718436 -0.00106635 0.709141" mass="3.7292" diaginertia="0.0412026 0.0406047 0.00639274"/>
              <joint name="right_knee_joint" pos="0 0 0" axis="0 1 0" range="0 2.653" actuatorfrcrange="-120 120" damping="5.0"/>
              <geom type="mesh" contype="0" conaffinity="0" group="1" density="0" rgba="0.75294 0.75294 0.75294 1" mesh="right_knee_link"/>
              <geom type="mesh" rgba="0.75294 0.75294 0.75294 1" mesh="right_knee_link"/>
              <body name="right_ankle_pitch_link" pos="0 0 -0.34">
                <inertial pos="0.0009 0 -0.0083" quat="0.5 0.5 0.5 0.5" mass="0.048544" diaginertia="1.12e-05 1.1e-05 1.033e-05"/>
                <joint name="right_ankle_pitch_joint" pos="0 0 0" axis="0 1 0" range="-0.873 0.524" actuatorfrcrange="-50 50" damping="3.0"/>
                <geom type="mesh" contype="0" conaffinity="0" group="1" density="0" rgba="0.75294 0.75294 0.75294 1" mesh="right_ankle_pitch_link"/>
                <geom type="mesh" rgba="0.75294 0.75294 0.75294 1" mesh="right_ankle_pitch_link"/>
                <body name="right_ankle_roll_link" pos="0 0 -0.018">
                  <inertial pos="0.041294 -0.0010615 -0.031752" quat="0 0.724505 0 0.68927" mass="0.70183" diaginertia="0.00240499 0.0023 0.000395012"/>
                  <joint name="right_ankle_roll_joint" pos="0 0 0" axis="1 0 0" range="-0.262 0.262" actuatorfrcrange="-50 50" damping="3.0"/>
                  <geom type="mesh" contype="0" conaffinity="0" group="1" density="0" rgba="0.75294 0.75294 0.75294 1" mesh="right_ankle_roll_link"/>
                  <!-- <geom type="mesh" rgba="0.75294 0.75294 0.75294 1" mesh="right_ankle_roll_link"/> -->
                  <geom type="box" rgba="1 0 0 0.5" pos="0.06 0 -0.038" size="0.10 0.035 0.006" contype="1" conaffinity="15" friction="1 0.005 0.0001"/>
                  <!-- <geom type="sphere" size="0.005" pos="-0.04 0.025 -0.04" rgba="1 0 0 0.5"/>
                  <geom type="sphere" size="0.005" pos="-0.04 -0.025 -0.04" rgba="1 0 0 0.5"/>
                  <geom type="sphere" size="0.005" pos="0.12 0.03 -0.04" rgba="1 0 0 0.5"/>
                  <geom type="sphere" size="0.005" pos="0.12 -0.03 -0.04" rgba="1 0 0 0.5"/> -->
                </body>
              </body>
            </body>
          </body>
        </body>
      </body>
      <body name="torso_link" pos="0 0 0.0619">
        <inertial pos="0.0061 0.0003 0.1879" quat="0.999977 0 0.00682264 0" mass="9.8779" diaginertia="0.15562 0.1368 0.0456795"/>
        <joint name="waist_yaw_joint" pos="0 0 0" axis="0 0 1" range="-2.79 2.79" actuatorfrcrange="-120 120" damping="4.0"/>
        <geom type="mesh" contype="0" conaffinity="0" group="1" density="0" rgba="0.75294 0.75294 0.75294 1" mesh="torso_link"/>
        <geom type="mesh" rgba="0.75294 0.75294 0.75294 1" mesh="torso_link"/>
        <body name="left_shoulder_pitch_link" pos="0 0.11963 0.3208" quat="0.99813 0.06105 0 0">
          <inertial pos="0.0033 0.0422 -0.0117" quat="0.99813 -0.06105 0 0" mass="0.8939" diaginertia="0.001 0.0007 0.0009"/>
          <joint name="left_shoulder_pitch_joint" pos="0 0 0" axis="0 1 0" range="-2.88 2.88" actuatorfrcrange="-50 50" damping="4.0"/>
          <geom type="mesh" contype="0" conaffinity="0" group="1" density="0" rgba="0.75294 0.75294 0.75294 1" mesh="left_shoulder_pitch_link" quat="0.99813 -0.06105 0 0"/>
          <geom type="mesh" rgba="0.75294 0.75294 0.75294 1" mesh="left_shoulder_pitch_link" quat="0.99813 -0.06105 0 0"/>
          <body name="left_shoulder_roll_link" pos="0 0.047187 -0.013786" quat="0.99813 -0.06105 0 0">
            <inertial pos="-0.0006 0.0016 -0.0673" mass="0.7787" diaginertia="0.0012 0.0013 0.0007"/>
            <joint name="left_shoulder_roll_joint" pos="0 0 0" axis="1 0 0" range="-0.175 2.2515" actuatorfrcrange="-50 50" damping="4.0"/>
            <geom type="mesh" contype="0" conaffinity="0" group="1" density="0" rgba="0.75294 0.75294 0.75294 1" mesh="left_shoulder_roll_link"/>
            <geom size="0.032 0.025" pos="0 0 -0.07" type="cylinder" rgba="0.75294 0.75294 0.75294 1"/>
            <body name="left_shoulder_yaw_link" pos="0 0 -0.1171">
              <inertial pos="0.0035409 -0.00073964 -0.044592" quat="0.99329 0 -0.115653 0" mass="0.35928" diaginertia="0.000923607 0.0008 0.000476393"/>
              <joint name="left_shoulder_yaw_joint" pos="0 0 0" axis="0 0 1" range="-2.618 2.618" actuatorfrcrange="-50 50" damping="4.0"/>
              <geom type="mesh" contype="0" conaffinity="0" group="1" density="0" rgba="0.75294 0.75294 0.75294 1" mesh="left_shoulder_yaw_link"/>
              <geom type="mesh" rgba="0.75294 0.75294 0.75294 1" mesh="left_shoulder_yaw_link"/>
              <body name="left_elbow_link" pos="0.01924 0 -0.0979">
                <inertial pos="0.0447 -0.0015 -0.0086458" quat="0.418542 0.595366 0.484402 0.485507" mass="1.48" diaginertia="0.00460603 0.00450553 0.00108844"/>
                <joint name="left_elbow_joint" pos="0 0 0" axis="0 1 0" range="-0.96 2.0944" actuatorfrcrange="-50 50" damping="4.0"/>
                <geom type="mesh" contype="0" conaffinity="0" group="1" density="0" rgba="0.75294 0.75294 0.75294 1" mesh="left_elbow_link"/>
                <geom type="mesh" rgba="0.75294 0.75294 0.75294 1" mesh="left_elbow_link"/>
                <body name="left_wrist_yaw_link" pos="0.138 0 -0.017415">
                  <inertial pos="0.025808 0.00016898 0.00074869" quat="0.5 0.5 0.5 0.5" mass="0.2728" diaginertia="0.0003 0.0003 0.0002"/>
                  <joint name="left_wrist_yaw_joint" pos="0 0 0" axis="1 0 0" range="-2.618 2.618" actuatorfrcrange="-50 50" damping="4.0"/>
                  <geom type="mesh" contype="0" conaffinity="0" group="1" density="0" rgba="0.75294 0.75294 0.75294 1" mesh="left_wrist_yaw_link"/>
                  <geom type="mesh" rgba="0.75294 0.75294 0.75294 1" mesh="left_wrist_yaw_link"/>
                </body>
              </body>
            </body>
          </body>
        </body>
        <body name="right_shoulder_pitch_link" pos="0 -0.11963 0.3208" quat="0.99813 -0.06105 0 0">
          <inertial pos="0.0032 -0.0422 -0.0117" quat="0.99813 0.06105 0 0" mass="0.8976" diaginertia="0.001 0.0007 0.0009"/>
          <joint name="right_shoulder_pitch_joint" pos="0 0 0" axis="0 1 0" range="-2.88 2.88" actuatorfrcrange="-50 50" damping="4.0"/>
          <geom type="mesh" contype="0" conaffinity="0" group="1" density="0" rgba="0.75294 0.75294 0.75294 1" mesh="right_shoulder_pitch_link" quat="0.99813 0.06105 0 0"/>
          <geom type="mesh" rgba="0.75294 0.75294 0.75294 1" mesh="right_shoulder_pitch_link" quat="0.99813 0.06105 0 0"/>
          <body name="right_shoulder_roll_link" pos="0 -0.047187 -0.013786" quat="0.99813 0.06105 0 0">
            <inertial pos="-0.0005 -0.0016 -0.0678" mass="0.7868" diaginertia="0.0012 0.0013 0.0007"/>
            <joint name="right_shoulder_roll_joint" pos="0 0 0" axis="1 0 0" range="-2.2515 0.175" actuatorfrcrange="-50 50" damping="4.0"/>
            <geom type="mesh" contype="0" conaffinity="0" group="1" density="0" rgba="0.75294 0.75294 0.75294 1" mesh="right_shoulder_roll_link"/>
            <geom type="cylinder" size="0.032 0.025" pos="0 0 -0.07"  rgba="0.75294 0.75294 0.75294 1"/>
            <body name="right_shoulder_yaw_link" pos="0 0 -0.1171">
              <inertial pos="0.0035415 0.0007384 -0.044591" quat="0.99329 0 -0.115653 0" mass="0.3593" diaginertia="0.000923607 0.0008 0.000476393"/>
              <joint name="right_shoulder_yaw_joint" pos="0 0 0" axis="0 0 1" range="-2.618 2.618" actuatorfrcrange="-50 50" damping="4.0"/>
              <geom type="mesh" contype="0" conaffinity="0" group="1" density="0" rgba="0.75294 0.75294 0.75294 1" mesh="right_shoulder_yaw_link"/>
              <geom type="mesh" rgba="0.75294 0.75294 0.75294 1" mesh="right_shoulder_yaw_link"/>
              <body name="right_elbow_link" pos="0.01924 0 -0.0979">
                <inertial pos="0.0447 0.0015 -0.0087" quat="0.418542 0.595366 0.484402 0.485507" mass="1.48" diaginertia="0.00460603 0.00450553 0.00108844"/>
                <joint name="right_elbow_joint" pos="0 0 0" axis="0 1 0" range="-0.96 2.0944" actuatorfrcrange="-50 50" damping="4.0"/>
                <geom type="mesh" contype="0" conaffinity="0" group="1" density="0" rgba="0.75294 0.75294 0.75294 1" mesh="right_elbow_link"/>
                <geom type="mesh" rgba="0.75294 0.75294 0.75294 1" mesh="right_elbow_link"/>
                <body name="right_wrist_yaw_link" pos="0.138 0 -0.017415">
                  <inertial pos="0.025808 -0.0001686 0.00074876" quat="0.5 0.5 0.5 0.5" mass="0.27279" diaginertia="0.0003 0.0003 0.0002"/>
                  <joint name="right_wrist_yaw_joint" pos="0 0 0" axis="1 0 0" range="-2.618 2.618" actuatorfrcrange="-50 50" damping="4.0"/>
                  <geom type="mesh" contype="0" conaffinity="0" group="1" density="0" rgba="0.75294 0.75294 0.75294 1" mesh="right_wrist_yaw_link"/>
                  <geom type="mesh" rgba="0.75294 0.75294 0.75294 1" mesh="right_wrist_yaw_link"/>
                </body>
              </body>
            </body>
          </body>
        </body>
        <body name="head_link" pos="0 0 0.4889">
          <inertial pos="0.0079 -0.0004 0.0262" quat="0.707107 0 0 0.707107" mass="0.7987" diaginertia="0.0022 0.0017 0.0017"/>
          <!-- <joint name="head_joint" pos="0 0 0" axis="0 0 1" range="-0.6981 0.6981"/> -->
          <geom type="mesh" contype="0" conaffinity="0" group="1" density="0" rgba="0.75294 0.75294 0.75294 1" mesh="head_link"/>
          <!-- <geom type="mesh" rgba="0.75294 0.75294 0.75294 1" mesh="head_link"/> -->
        </body>
      </body>
    </body>
  </worldbody>

  <actuator>        
    <motor name="left_hip_pitch_joint" joint="left_hip_pitch_joint"/>
    <motor name="left_hip_roll_joint" joint="left_hip_roll_joint"/>
    <motor name="left_hip_yaw_joint" joint="left_hip_yaw_joint"/>
    <motor name="left_knee_joint" joint="left_knee_joint"/>
    <motor name="left_ankle_pitch_joint" joint="left_ankle_pitch_joint"/>
    <motor name="left_ankle_roll_joint" joint="left_ankle_roll_joint"/>
    <motor name="right_hip_pitch_joint" joint="right_hip_pitch_joint"/>
    <motor name="right_hip_roll_joint" joint="right_hip_roll_joint"/>
    <motor name="right_hip_yaw_joint" joint="right_hip_yaw_joint"/>
    <motor name="right_knee_joint" joint="right_knee_joint"/>
    <motor name="right_ankle_pitch_joint" joint="right_ankle_pitch_joint"/>
    <motor name="right_ankle_roll_joint" joint="right_ankle_roll_joint"/>
    <motor name="waist_yaw_joint" joint="waist_yaw_joint"/>
    <motor name="left_shoulder_pitch_joint" joint="left_shoulder_pitch_joint"/>
    <motor name="left_shoulder_roll_joint" joint="left_shoulder_roll_joint"/>
    <motor name="left_shoulder_yaw_joint" joint="left_shoulder_yaw_joint"/>
    <motor name="left_elbow_joint" joint="left_elbow_joint"/>
    <motor name="left_wrist_yaw_joint" joint="left_wrist_yaw_joint"/>
    <motor name="right_shoulder_pitch_joint" joint="right_shoulder_pitch_joint"/>
    <motor name="right_shoulder_roll_joint" joint="right_shoulder_roll_joint"/>
    <motor name="right_shoulder_yaw_joint" joint="right_shoulder_yaw_joint"/>
    <motor name="right_elbow_joint" joint="right_elbow_joint"/>
    <motor name="right_wrist_yaw_joint" joint="right_wrist_yaw_joint"/>
  </actuator>
  
  <sensor>
    <jointpos joint="left_hip_pitch_joint" user="6" name='pos_left_hip_pitch'/>
    <jointpos joint="left_hip_roll_joint" user="6" name='pos_left_hip_roll'/>
    <jointpos joint="left_hip_yaw_joint" user="6" name='pos_left_hip_yaw'/>
    <jointpos joint="left_knee_joint" user="6" name='pos_left_knee'/>
    <jointpos joint="left_ankle_pitch_joint" user="6" name='pos_left_ankle_pitch'/>
    <jointpos joint="left_ankle_roll_joint" user="6" name='pos_left_ankle_roll'/>

    <jointpos joint="right_hip_pitch_joint" user="6" name='pos_right_hip_pitch'/>
    <jointpos joint="right_hip_roll_joint" user="6" name='pos_right_hip_roll'/>
    <jointpos joint="right_hip_yaw_joint" user="6" name='pos_right_hip_yaw'/>
    <jointpos joint="right_knee_joint" user="6" name='pos_right_knee'/>
    <jointpos joint="right_ankle_pitch_joint" user="6" name='pos_right_ankle_pitch'/>
    <jointpos joint="right_ankle_roll_joint" user="6" name='pos_right_ankle_roll'/>

    <jointpos joint="waist_yaw_joint" user="6" name='pos_waist_yaw'/>

    <jointpos joint="left_shoulder_pitch_joint" user="6" name='pos_left_shoulder_pitch'/>
    <jointpos joint="left_shoulder_roll_joint" user="6" name='pos_left_shoulder_roll'/>
    <jointpos joint="left_shoulder_yaw_joint" user="6" name='pos_left_shoulder_yaw'/>
    <jointpos joint="left_elbow_joint" user="6" name='pos_left_elbow'/>
    <jointpos joint="left_wrist_yaw_joint" user="6" name='pos_left_wrist_yaw'/>

    <jointpos joint="right_shoulder_pitch_joint" user="6" name='pos_right_shoulder_pitch'/>
    <jointpos joint="right_shoulder_roll_joint" user="6" name='pos_right_shoulder_roll'/>
    <jointpos joint="right_shoulder_yaw_joint" user="6" name='pos_right_shoulder_yaw'/>
    <jointpos joint="right_elbow_joint" user="6" name='pos_right_elbow'/>
    <jointpos joint="right_wrist_yaw_joint" user="6" name='pos_right_wrist_yaw'/>

    <jointvel joint="left_hip_pitch_joint" user="6" name='vel_left_hip_pitch'/>
    <jointvel joint="left_hip_roll_joint" user="6" name='vel_left_hip_roll'/>
    <jointvel joint="left_hip_yaw_joint" user="6" name='vel_left_hip_yaw'/>
    <jointvel joint="left_knee_joint" user="6" name='vel_left_knee'/>
    <jointvel joint="left_ankle_pitch_joint" user="6" name='vel_left_ankle_pitch'/>
    <jointvel joint="left_ankle_roll_joint" user="6" name='vel_left_ankle_roll'/>

    <jointvel joint="right_hip_pitch_joint" user="6" name='vel_right_hip_pitch'/>
    <jointvel joint="right_hip_roll_joint" user="6" name='vel_right_hip_roll'/>
    <jointvel joint="right_hip_yaw_joint" user="6" name='vel_right_hip_yaw'/>
    <jointvel joint="right_knee_joint" user="6" name='vel_right_knee'/>
    <jointvel joint="right_ankle_pitch_joint" user="6" name='vel_right_ankle_pitch'/>
    <jointvel joint="right_ankle_roll_joint" user="6" name='vel_right_ankle_roll'/>

    <jointvel joint="waist_yaw_joint" user="6" name='vel_waist_yaw'/>

    <jointvel joint="left_shoulder_pitch_joint" user="6" name='vel_left_shoulder_pitch'/>
    <jointvel joint="left_shoulder_roll_joint" user="6" name='vel_left_shoulder_roll'/>
    <jointvel joint="left_shoulder_yaw_joint" user="6" name='vel_left_shoulder_yaw'/>
    <jointvel joint="left_elbow_joint" user="6" name='vel_left_elbow'/>
    <jointvel joint="left_wrist_yaw_joint" user="6" name='vel_left_wrist_yaw'/>

    <jointvel joint="right_shoulder_pitch_joint" user="6" name='vel_right_shoulder_pitch'/>
    <jointvel joint="right_shoulder_roll_joint" user="6" name='vel_right_shoulder_roll'/>
    <jointvel joint="right_shoulder_yaw_joint" user="6" name='vel_right_shoulder_yaw'/>
    <jointvel joint="right_elbow_joint" user="6" name='vel_right_elbow'/>
    <jointvel joint="right_wrist_yaw_joint" user="6" name='vel_right_wrist_yaw'/>

    <framequat name='orientation' objtype='site' noise='0.001' objname='imu'/>
    <framepos name='position' objtype='site' noise='0.001' objname='imu'/>
    <gyro name='angular-velocity' site='imu' noise='0.005' cutoff='34.9'/>
    <velocimeter name='linear-velocity' site='imu' noise='0.001' cutoff='30'/>
  </sensor>

  <statistic center="1.0 0.7 1.0" extent="0.8"/>

  <visual>
    <headlight diffuse="0.6 0.6 0.6" ambient="0.1 0.1 0.1" specular="0.9 0.9 0.9"/>
    <rgba haze="0.15 0.25 0.35 1"/>
    <global azimuth="-140" elevation="-20"/>
  </visual>

  <asset>
    <texture type="skybox" builtin="flat" rgb1="0 0 0" rgb2="0 0 0" width="512" height="3072"/>
    <texture type="2d" name="groundplane" builtin="checker" mark="edge" rgb1="0.2 0.3 0.4" rgb2="0.1 0.2 0.3" markrgb="0.8 0.8 0.8" width="300" height="300"/>
    <material name="groundplane" texture="groundplane" texuniform="true" texrepeat="5 5" reflectance="0.2"/>
  </asset>

  <worldbody>
    <light pos="1 0 3.5" dir="0 0 -1" directional="true"/>
    <geom name="floor" size="0 0 0.05" type="plane" material="groundplane" friction="1.2 0.02 0.001"/>
  </worldbody>
</mujoco>
